# *Interview Collection For FE/JavaScript*



## 2、面试题汇集
1. 题目一
    
    ```
    var a = 1;
    function foo(a){
      a = 2
      console.log('inner:', a) // 2
    }
    foo(a)
    console.log('out:', a) // 1

    1.使用var声明变量，在方法内部是局部变量，在方法外部是全局变量
    2.没有使用var声明的变量，在方法内部或外部都是全局变量，但如果是在方
    法内部声明，在方法外部使用之前需要先调用方法，告知系统声明了全局变量后方可在方法外部使用。
    
    在函数作用域内 加var定义的变量是局部变量,不加var定义的就成了全局变量
    在function内部， 加var的是局部变量， 不加var的则是全局变量；
    在function外部， 不管有没有使用var声明变量，都是全局变量，在function外部,var关
    键字一般可以省略，但是为了书写规范和维护方便以及可读性好，我个人不建议省略var关键字!
    ```

    

2. 题目二
    
    ```
    var a = 1;
    function func(a, b){
      console.log(arguments) // Arguments [1, callee: f, Symbol(Symbol.iterator): f]
      a = 2;
      arguments[0] = 3;
      arguments[1] = 4;
      var a;
      console.log(a, this.a, b) // 3  1  undefined
    }
    func(a)
    ```

3. 题目三

    ```
    // function  中 return this 是代表什么？
    // 如果return的是Object。这种情况下，不再返回this对象，而是返回return语句的返回值。

    String.prototype.self = function(){ return this }
    var a = 'str';
    var b = a.self();
    console.log(a); // 'str'
    console.log(b); // String {'str'}
    
    // valueOf() 方法返回一个String对象的原始值(primitive value)，该值等同于String.prototype.toString()
    
    console.log(a === b, a.vulueOf() === b.valueOf(), typeof a, typeof b) 
    // false true 'string' 'object'

    console.log('str' === new String('str')) // false

    console.log('str' === ['s', 't', 'r'].join('').toString()) //true

    console.log(String('str') === 'str') // true

    console.log(String('str') === new String('str')) // false

    ```

4. 题目四
    
    ```
    function a(){
      console.log(1)
    }
    var foo = function(){
      return new Promise(function(resolve, reject){
        resolve(2)
        console.log(3)
      })
    }
    a()
    foo().then(function(data){
      console.log(data);
      console.log(4)
    })
    setTimeout(function(){
      console.log(5)
    }, 0)
    // 结果 :
    // 1
    // 3
    // 2
    // 4
    // 5
    ```

5. 题目五
    
    ```
    console.log(!'') // true
    console.log(!{}) // false
    console.log(![]) // false
    console.log(!0) // true
    console.log(!1) // false
    console.log(!null) // true
    console.log(!undefined) // true
    ```

6. 题目六

    ```
    const promise = new Promise((resolve, reject)=>{
      console.log(1)
      resolve()
      console.log(2)
    })
    promise.then(()=>{
      console.log(3)
    })
    console.log(4)
    // 结果：
    // 1
    // 2
    // 4
    // 3
    解释：Promise构造函数是同步执行的，promise.then中的函数是异步执行的。
    ```

7. 题目七
    
    ```
    const promise1 = new Promise((resolve, reject)=>{
      setTimeout(()=>{
        resolve('success')
      }, 1000)
    })
    const promise2 = promise1.then(()=>{
      throw new Error('error !!')
    })
    console.log('promise1',promise1)
    console.log('promise2',promise2)
    setTimeout(()=>{
      console.log('promise1',promise1)
      console.log('promise2',promise2)
    }, 2000)
    // 结果：
    // promise1 Promise {<pending>}
		// promise2 Promise {<pending>}
		// Uncaught (in promise) Error: error !!
		// promise1 Promise {<fulfilled>: "success"}
		// promise2 Promise {<rejected>: Error: error !!


    解释：promise有三种状态：pending、fulfilled、或rejected。
    状态改变只能是 pending->fulfilled 或者 pending->rejected，状态一旦改变则不能再变。
    上面 promise2 并不是 promise1，而是返回的一个新的 Promise 实例。
    ```
  
8. 题目八

    ```
    const promise = new Promise((resolve, reject)=>{
      resolve('success1')
      reject('error')
      resolve('success2')
    })
    promise.then((res)=>{
      console.log('then', res)
    })
    .catch((err)=>{
      console.log('catch:', err)
    })
    // 结果：
    // then: success1
    // Promise {<fulfilled>: undefined}
    解释：构造函数中resolve或reject只有第一次执行有效，
    多次调用没有任何作用，即promise状态一旦改变则不能再变
    ```

9. 题目九

    ```
    Promise.resolve(1)
      .then((res) => {
        console.log(res)
        return 2
      })
      .catch((err) => {
        return 3
      })
      .then((res) => {
        console.log(res)
      })
    // 结果：
    // 1
    // 2
    解释：promise可以链式调用。提起链式调用我们通常会想到return this实现，不过Promise并不是这样实现的。
    promise每次调用.then或者.catch都会返回一个新的promise，从而实现了链式调用
    ```

10. 题目十

    ```
    const promise = new Promise((resolve, reject) => {
      setTimeout(() => {
        console.log('once')
        resolve('success')
      }, 1000)
    })
      
    const start = Date.now()
    console.log(start)
    promise.then((res) => {
      console.log(res, Date.now(), Date.now() - start)
    })
    promise.then((res) => {
      console.log(res, Date.now(), Date.now() - start)
    })
    // 结果:
    // 1555950300600
    // once
    // success 1555950301600 1000
    // success 1555950301601 1001
    解析：promise 的 .then 或者 .catch 可以被调用多次，但这里 Promise 构造函数只执行一次。
    或者说 promise 内部状态一经改变，并且有了一个值，那么后续每次调用 .then 或者 .catch 都会直接拿到该值。
    ```

11. 题目十一
    
    ```
    Promise.resolve()
      .then(() => {
        return new Error('error!!!')
      })
      .then((res) => {
        console.log('then: ', res)
      })
      .catch((err) => {
        console.log('catch: ', err)
    // 结果：
    // then: Error: error!!!
      at Promise.resolve.then (...)
      at ...
    解释：.then 或者 .catch 中 return 一个 error 对象并不会抛出错误，所以不会被后续的 .catch 捕获，需要改成其中一种：
    return Promise.reject(new Error('error!!!')) 或者
    throw new Error('error!!!')
    因为返回任意一个非 promise 的值都会被包裹成 promise 对象，
    即 return new Error('error!!!') 等价于 return Promise.resolve(new Error('error!!!'))
    ```

12. 题目十二

    ```
    const promise = Promise.resolve()
      .then(() => {
        return promise
      })
    promise.catch(console.error)
    // 结果：
    TypeError: Chaining cycle detected for promise #<Promise>
    at <anonymous>
    at process._tickCallback (internal/process/next_tick.js:188:7)
    at Function.Module.runMain (module.js:667:11)
    at startup (bootstrap_node.js:187:16)
    at bootstrap_node.js:607:3
    解释：.then 或 .catch 返回的值不能是 promise 本身，否则会造成死循环。类似于：
    ```

13. 题目十三

    ```
    Promise.resolve(1)
      .then(2)
      .then(Promise.resolve(3))
      .then(console.log)
    // 结果：
    // 1
    解释：.then 或者 .catch 的参数期望是函数，传入非函数则会发生值穿透。
    ```

14. 题目十四

    ```
    Promise.resolve()
      .then(function success (res) {
        throw new Error('error')
      }, function fail1 (e) {
        console.error('fail1: ', e)
      })
      .catch(function fail2 (e) {
        console.error('fail2: ', e)
      })
    // 结果：
    // fail2: Error: error
    // at success (...)
    // at ...
    ```

    解释：.then 可以接收两个参数，第一个是处理成功的函数，第二个是处理错误的函数。
    .catch 是 .then 第二个参数的简便写法，但是它们用法上有一点需要注意：
    .then 的第二个处理错误的函数捕获不了第一个处理成功的函数抛出的错误，而后续的 .catch 可以捕获之前的错误。当然以下代码也可以：
    
    ```
    Promise.resolve()
      .then(function success1 (res) {
        throw new Error('error')
      }, function fail1 (e) {
        console.error('fail1: ', e)
      })
      .then(function success2 (res) {
      }, function fail2 (e) {
        console.error('fail2: ', e)
      })
    ```

15. 题目十五

    ```
    process.nextTick(() => {
      console.log('nextTick')
    })
    Promise.resolve()
      .then(() => {
        console.log('then')
      })
    setImmediate(() => {
      console.log('setImmediate')
    })
    console.log('end')
    // 结果：
    // end
    // nextTick
    // then
    // setImmediate
    ```

    解释：process.nextTick 和 promise.then 都属于 microtask，而 setImmediate 属于 macrotask，在事件循环的 check 阶段执行。
    事件循环的每个阶段（macrotask）之间都会执行 microtask，事件循环的开始会先执行一次 microtask。


## 3、面试题
https://www.jianshu.com/p/d50015adad69
1.  (a). 给出下面代码的输出结果
    ```
    function createFunctions(){
      var result = [];
      for(var i = 0; i < 10; i++){
        result[i] = function(){
          return i;
        }
      }
      return result;
    }
    var result = createFunctions();
    console.log(result[5]());
    // 结果 ： 10
    ```
    
    (b).上述输出结果是否达到预期结果，如果不是，有什么改进?
    
    ```
    // 改进（1）：
    function createFunctions(){
      var result = [];
      for(var i = 0; i < 10; i++){
        result[i] = (function(num){
          return num;
        })(i)
      }
      return result;
    }
    var result = createFunctions();
    console.log(result[5]) //输出结果：5
    /**
    解析：改进前的，i永远都是那个i(相当于一个指针)，存在result数组里面的值其实就是指针i，
    指向的那个具体的值也是同一个，随着循环不断在变化，循环完成，值固定了（等10），
    数组里装的值也就定下来了(全部是10)
    改进后：借用立即执行函数，(function(){})(i)，立即执行函数是把i作为参数传到函数里面。
    好处是：参数按值传递，这样函数获得的i就不是一个指针了，而是i的一个副本。
    那么，数组里面的各个值(函数执行后返回的值)就毫无瓜葛。
    */

    // 改进(2):
		function createFunctions(){
			var result = [];
			for(var i = 0; i < 10; i++){
				result[i] = (function(num){
					return function(){return num};
				})(i)
			}
			return result;
		}
		var result = createFunctions();
		console.log(result[5]()) //输出结果：5
    /**
    解析：改进(1)中，立即执行函数是return num，可直接得到数组中num值，
    后面的return function(){return num}, 返回的是一个函数，数组中的存的也是函数，
    获取值时候要调用数组中的函数以得到函数的值
    */
    ```

2. 请给出下面代码输出结果
    
    ```
    var b = 1;
    function outer(){
      var b = 2;
      function inner(){
        b++;
        console.log(b);
        var b = 3;
        console.log(b);
      }
      inner();
    }
    outer();
    // 结果：
    // NaN
    // 3
    ```

    上述inner()函数相当于

    ```
    function inner () {
    //变量提升
      var b; // b is undefined
      b++; // b is NaN
      console.log(b);
      b = 3; // b is 3
      console.log(b); // output "3"
    }
    ```

3. 请给出下面代码输出结果
  
    ```
    var name = 'name1';
    var object = {
      name: 'object name',
      getName: function(){
        return function(){
          return this.name;
        }
      }
    }
    console.log(object.getName()());
    // 结果：name1
    上述输出结果是否达到预期结果，如果不是，有什么改进方法
    ```

4. 请给出下面代码输出结果
    
    ```
    (function (){
      try {
        throw new Error();
      } catch (x){
        var x = 1, y = 2;
        console.log(x);
      }
      console.log(x);
      console.log(y);
    })()
    // 输出:
    // 1
    // undefined
    // 2
    ```
    
    解析：var语句被提升（没有它们的值初始化）到它所属的全局或函数作用域的顶部，
    即使它位于with或catch块内。但是，错误的标识符只在catch块内部可见。它相当于：
    
    ```
    (function(){
      var x, y; // outer and hoisted
      try {
        throw new Error();
      } catch (x){ // inner
        x = 1; // inner x, not the outer one
        y = 2; // there is only one y, which is in the outer scope
        console.log(x) //inner
      }
      console.log(x);
      console.log(y);
    })();
    ```

5. 请给出下面代码输出结果
    
    ```
    console.log(`0 || 1 = ${(0 || 1)}`); // 0 || 1 = 1
    console.log(`1 || 2 = ${(1 || 2)}`); // 1 || 2 = 1
    console.log(`0 && 1 = ${(0 && 1)}`); // 0 && 1 = 0
    console.log(`1 && 2 = ${(1 && 2)}`); // 1 && 2 = 2
    console.log(false == '0'); // true
    console.log(false === '0'); // false
    console.log(1 < 2 < 3); // true
    console.log(3 > 2 > 1); // true
    ```

6. 按照要求实现Person和Student对象
    * a. student继承Person
    * b. Person包含一个实例变量name，包含一个方法printName
    * c. Student包含一个实例变量score，包含一个实例方法printScore
    * d. 所有Person和Student对象之间共享一个方法
    
    ```
    function Person(name){
      this.name=name||'Person';
      this.printName = function(){
        document.write(name)
      };
    }
    Person.prototype.sayname=function () {
      alert(this.name);
    }
    function Student(name,score) {
      Person.call(this,name);
      this.score = score;
    }
    Student.prototype=new Person;
    Student.prototype.printScore=function () {
        document.write(this.score)
    }
    var xiaoMing=new Student("xiaoMing",23);
    xiaoMing.sayname();
    xiaoMing.printScore();
    ```


7. 整数数组，数组中连续的一个或者多个整数组成一个子数组，每个子数组都有一个和，求所有子数组的和的最大值，
例 [1,-2,3,10,-4,7,2,-5]，最大的子数组为[3,10,-4,7,2]，那么输出的该子数组的和是18，尽量考虑时间复杂度
    
    思路：
    * 遍历数组，遇到负的和则放弃之前的结果，重新积累，这期间保留最大值；
    * 用sum记录最终返回的最大和，用tempsum记录累计值；
    * 对于数组中的一个数array[i]，若其左边的累加和非负,那么加上array[i]；
    * 判断此时的tempsum是否大于sum，若大于此时的sum，则用sum记录下来。

    echoVic 链接：https://www.jianshu.com/p/9ed5fa86361e

    ```
    function FindGreatestSumOfSubArray(array) {
      if (array.length < 0) return 0;
      var sum = array[0],
        tempsum = array[0]; //注意初始值 不能设为0 防止只有负数        
      for (var i = 1; i < array.length; i++) {
        tempsum = (tempsum < 0) ? array[i] : tempsum + array[i];
        sum = (tempsum > sum) ? tempsum : sum;
      }
      return sum;
    }
    ```

## 4、集锦
1. 写出如下代码运行结果：
    ```
    function C1(name){
      if(name) this.name = name;
    }
    function C2(name){
      this.name = name;
    }
    function C3(name){
      this.name = name || 'John'
    }
    C1.prototype.name = 'Tom';
    C2.prototype.name = 'Tom';
    C3.prototype.name = 'Tom';
    alert(
      (new C1()).name + (new C2()).name + (new C3()).name
    )
    // 结果： TomundefinedJohn
    // 解析：C1,if不成立，new C1()中没有name属性，就访问到了原型上的name，输出tom
    C2,既然没有参数，也就是执行new C2(undefined)，所以name为undefined
    C3,new C3()的name值为john，所输出john
    ```
  
2. 写出如下代码运行结果
    
    ```
    window.number = 1;
    var obj = {
      'number': 4,
      'dbl': (function(){
        this.number *= 2;
        return function(){
          this.number *= 2;
        }
      })()
    }
    var dbl = obj.dbl;
    dbl();
    obj.dbl();
    console.log(window.number+obj.number)
    // 结果 ： 12
    // 解析：关键是this的指向问题，在 this 有所属对象时就指向所属对象，
    没有所属对象就指向全局对象。全局作用域 number 、 obj
    局部作用域 obj.nujber 、 obj.dbl。obj.dbl 为立即执行函数
    window.number = 1 * 2 = 2
    执行结果为一个匿名函数
    ```

3. 